<?xml version="1.0" ?>
<!-- =================================================================================== -->
<!-- |    This document was autogenerated by xacro from wifibot.xacro                  | -->
<!-- |    EDITING THIS FILE BY HAND IS NOT RECOMMENDED                                 | -->
<!-- =================================================================================== -->
<robot name="Wifibot" xmlns:xacro="http://www.ros.org/wiki/xacro">
  <link name="base_link"/>
  <joint name="j_wifibot_attachment" type="fixed">
    <parent link="base_link"/>
    <child link="MP_BODY"/>
    <origin rpy="0 0 0" xyz="0 0 0"/>
  </joint>
  <link name="MP_BODY">
    <inertial>
      <origin xyz="0 0 0"/>
      <mass value="3.2"/>
      <inertia ixx="0.063253" ixy="0.0552" ixz="0.0192" iyy="0.102826" iyz="0.01472" izz="0.152426"/>
    </inertial>
    <visual>
      <!--origin xyz="-0.0235 0 -0.03525" rpy="0 0 0" /-->
      <origin rpy="0 0 0" xyz="0 0 0"/>
      <geometry>
        <!--box size="0.102 0.109 0.106" /-->
        <mesh filename="/home/pierre/PycharmProjects/lightning_rl/lightning_rl/simple_driving/ressources/wifibot/meshes/base.stl" scale="1 1 1"/>
      </geometry>
      <material name="Grey">
        <color rgba="0.20 0.20 0.20 1.0"/>
      </material>
    </visual>
    <collision>
      <origin rpy="0 0 0" xyz="0 0 0"/>
      <geometry>
        <mesh filename="/home/pierre/PycharmProjects/lightning_rl/lightning_rl/simple_driving/ressources/wifibot/meshes/base.stl" scale="1 1 1"/>
      </geometry>
    </collision>
  </link>
  <gazebo reference="MP_BODY">
    <material>Gazebo/Grey</material>
  </gazebo>
  <link name="wheel_fl">
    <inertial>
      <origin rpy="0 0 0" xyz="0 -0.0 0"/>
      <mass value="0.15"/>
      <inertia ixx="0.0002909" ixy="0.0" ixz="0.0" iyy="0.0002909" iyz="0.0" izz="0.000421"/>
    </inertial>
    <visual>
      <origin rpy="0 0 0" xyz="0 0 0"/>
      <geometry>
        <mesh filename="/home/pierre/PycharmProjects/lightning_rl/lightning_rl/simple_driving/ressources/wifibot/meshes/wheel.stl" scale="1 1 1"/>
      </geometry>
      <material name="Grey">
        <color rgba="0.20 0.20 0.20 1.0"/>
      </material>
    </visual>
    <collision>
      <origin rpy="0 0 0" xyz="0 -0.0 0"/>
      <geometry>
        <mesh filename="/home/pierre/PycharmProjects/lightning_rl/lightning_rl/simple_driving/ressources/wifibot/meshes/wheel.stl" scale="1 1 1"/>
      </geometry>
      <surface>
        <bounce>
          <restitution_coefficient> 0.1 </restitution_coefficient>
        </bounce>
      </surface>
    </collision>
  </link>
  <joint name="j_wheel_fl" type="continuous">
    <parent link="MP_BODY"/>
    <child link="wheel_fl"/>
    <origin rpy="0 0 -1.570796" xyz="0.0775 0.15 0.0"/>
    <axis xyz="1 0 0"/>
    <limit effort="20" velocity="20"/>
    <dynamics damping="0.01" friction="0.1"/>
  </joint>
  <transmission name="t_wheel_fl">
    <type>transmission_interface/SimpleTransmission</type>
    <joint name="j_wheel_fl">
      <hardwareInterface>hardware_interface/EffortJointInterface</hardwareInterface>
    </joint>
    <actuator name="m_wheel_fl">
      <hardwareInterface>hardware_interface/EffortJointInterface</hardwareInterface>
      <mechanicalReduction>1</mechanicalReduction>
    </actuator>
  </transmission>
  <gazebo reference="wheel_fl">
    <material>Gazebo/Grey</material>
  </gazebo>
  <link name="wheel_fr">
    <inertial>
      <origin rpy="0 0 0" xyz="0 -0.0 0"/>
      <mass value="0.15"/>
      <inertia ixx="0.0002909" ixy="0.0" ixz="0.0" iyy="0.0002909" iyz="0.0" izz="0.000421"/>
    </inertial>
    <visual>
      <origin rpy="0 0 0" xyz="0 0 0"/>
      <geometry>
        <mesh filename="/home/pierre/PycharmProjects/lightning_rl/lightning_rl/simple_driving/ressources/wifibot/meshes/wheel.stl" scale="1 1 1"/>
      </geometry>
      <material name="Grey">
        <color rgba="0.20 0.20 0.20 1.0"/>
      </material>
    </visual>
    <collision>
      <origin rpy="0 0 0" xyz="0 -0.0 0"/>
      <geometry>
        <mesh filename="/home/pierre/PycharmProjects/lightning_rl/lightning_rl/simple_driving/ressources/wifibot/meshes/wheel.stl" scale="1 1 1"/>
      </geometry>
      <surface>
        <bounce>
          <restitution_coefficient> 0.1 </restitution_coefficient>
        </bounce>
      </surface>
    </collision>
  </link>
  <joint name="j_wheel_fr" type="continuous">
    <parent link="MP_BODY"/>
    <child link="wheel_fr"/>
    <origin rpy="0 0 1.570796" xyz="0.0775 -0.15 0.0"/>
    <axis xyz="1 0 0"/>
    <limit effort="20" velocity="20"/>
    <dynamics damping="0.01" friction="0.1"/>
  </joint>
  <transmission name="t_wheel_fr">
    <type>transmission_interface/SimpleTransmission</type>
    <joint name="j_wheel_fr">
      <hardwareInterface>hardware_interface/EffortJointInterface</hardwareInterface>
    </joint>
    <actuator name="m_wheel_fr">
      <hardwareInterface>hardware_interface/EffortJointInterface</hardwareInterface>
      <mechanicalReduction>1</mechanicalReduction>
    </actuator>
  </transmission>
  <gazebo reference="wheel_fr">
    <material>Gazebo/Grey</material>
  </gazebo>
  <link name="wheel_rl">
    <inertial>
      <origin rpy="0 0 0" xyz="0 -0.0 0"/>
      <mass value="0.15"/>
      <inertia ixx="0.0002909" ixy="0.0" ixz="0.0" iyy="0.0002909" iyz="0.0" izz="0.000421"/>
    </inertial>
    <visual>
      <origin rpy="0 0 0" xyz="0 0 0"/>
      <geometry>
        <mesh filename="/home/pierre/PycharmProjects/lightning_rl/lightning_rl/simple_driving/ressources/wifibot/meshes/wheel.stl" scale="1 1 1"/>
      </geometry>
      <material name="Grey">
        <color rgba="0.20 0.20 0.20 1.0"/>
      </material>
    </visual>
    <collision>
      <origin rpy="0 0 0" xyz="0 -0.0 0"/>
      <geometry>
        <mesh filename="/home/pierre/PycharmProjects/lightning_rl/lightning_rl/simple_driving/ressources/wifibot/meshes/wheel.stl" scale="1 1 1"/>
      </geometry>
      <surface>
        <bounce>
          <restitution_coefficient> 0.1 </restitution_coefficient>
        </bounce>
      </surface>
    </collision>
  </link>
  <joint name="j_wheel_rl" type="continuous">
    <parent link="MP_BODY"/>
    <child link="wheel_rl"/>
    <origin rpy="0 0 -1.570796" xyz="-0.0775 0.15 0.0"/>
    <axis xyz="1 0 0"/>
    <limit effort="20" velocity="20"/>
    <dynamics damping="0.01" friction="0.1"/>
  </joint>
  <transmission name="t_wheel_rl">
    <type>transmission_interface/SimpleTransmission</type>
    <joint name="j_wheel_rl">
      <hardwareInterface>hardware_interface/EffortJointInterface</hardwareInterface>
    </joint>
    <actuator name="m_wheel_rl">
      <hardwareInterface>hardware_interface/EffortJointInterface</hardwareInterface>
      <mechanicalReduction>1</mechanicalReduction>
    </actuator>
  </transmission>
  <gazebo reference="wheel_rl">
    <material>Gazebo/Grey</material>
  </gazebo>
  <link name="wheel_rr">
    <inertial>
      <origin rpy="0 0 0" xyz="0 -0.0 0"/>
      <mass value="0.15"/>
      <inertia ixx="0.0002909" ixy="0.0" ixz="0.0" iyy="0.0002909" iyz="0.0" izz="0.000421"/>
    </inertial>
    <visual>
      <origin rpy="0 0 0" xyz="0 0 0"/>
      <geometry>
        <mesh filename="/home/pierre/PycharmProjects/lightning_rl/lightning_rl/simple_driving/ressources/wifibot/meshes/wheel.stl" scale="1 1 1"/>
      </geometry>
      <material name="Grey">
        <color rgba="0.20 0.20 0.20 1.0"/>
      </material>
    </visual>
    <collision>
      <origin rpy="0 0 0" xyz="0 -0.0 0"/>
      <geometry>
        <mesh filename="/home/pierre/PycharmProjects/lightning_rl/lightning_rl/simple_driving/ressources/wifibot/meshes/wheel.stl" scale="1 1 1"/>
      </geometry>
      <surface>
        <bounce>
          <restitution_coefficient> 0.1 </restitution_coefficient>
        </bounce>
      </surface>
    </collision>
  </link>
  <joint name="j_wheel_rr" type="continuous">
    <parent link="MP_BODY"/>
    <child link="wheel_rr"/>
    <origin rpy="0 0 1.570796" xyz="-0.0775 -0.15 0.0"/>
    <axis xyz="1 0 0"/>
    <limit effort="20" velocity="20"/>
    <dynamics damping="0.01" friction="0.1"/>
  </joint>
  <transmission name="t_wheel_rr">
    <type>transmission_interface/SimpleTransmission</type>
    <joint name="j_wheel_rr">
      <hardwareInterface>hardware_interface/EffortJointInterface</hardwareInterface>
    </joint>
    <actuator name="m_wheel_rr">
      <hardwareInterface>hardware_interface/EffortJointInterface</hardwareInterface>
      <mechanicalReduction>1</mechanicalReduction>
    </actuator>
  </transmission>
  <gazebo reference="wheel_rr">
    <material>Gazebo/Grey</material>
  </gazebo>
  <gazebo>
    <plugin filename="libgazebo_ros_control.so" name="gazebo_ros_control">
      <robotNamespace>/wifibot</robotNamespace>
    </plugin>
  </gazebo>
</robot>

